Workbook

Sheet 说明与统计
A1: 沿海地区土木类 2027届秋招岗位汇总 —— 说明与统计
A3: 求职者 | B3: 王卓｜华侨大学 土木工程（结构工程）学术型硕士｜2027届
A4: 求职意向 | B4: 钢结构工程师 / 结构设计 / 桥梁工程
A5: 研究方向 | B5: 桥梁钢结构涂层腐蚀与损伤识别（盐雾试验、CT、红外热成像、三维扫描、SEM/EDS、XRD）
A6: 检索范围 | B6: 辽宁、河北、天津、山东、江苏、上海、浙江、福建、广东、广西、海南（另含总部在外、在沿海有岗位的全国性单位）
A7: 检索日期 | B7: 2026-10-20
A8: 信息来源 | B8: 牛企直聘校招、国企招聘网等第三方转载，以及高校就业网。本环境无法直接打开企业官网，日期与入口请投递前二次核对。
A10: 统计项（自动计算） | B10: 数量 | D10: 说明
A11: 已发布公告单位数 | B11: =COUNTA(27届已发布!D4:D84) -> 81 | D11: “27届已发布”工作表
A12: 其中：进行中 | B12: =COUNTIF(27届已发布!L4:L84,"进行中") -> 16 | D12: 截止日期距今超过7天
A13: 其中：7天内截止 | B13: =COUNTIF(27届已发布!L4:L84,"7天内截止") -> 6 | D13: 优先处理
A14: 其中：今日截止 | B14: =COUNTIF(27届已发布!L4:L84,"今日截止") -> 2
A15: 其中：已启动·截止待核 | B15: =SUMPRODUCT(--(LEFT(27届已发布!L4:L84,3)="已启动")) -> 37 | D15: 已见公告但未检索到截止日，尽快去官网确认
A16: 其中：已截止 | B16: =COUNTIF(27届已发布!L4:L84,"已截止") -> 19 | D16: 可联系HR问补录或等春招
A17: 已发布中高匹配（★★★） | B17: =COUNTIF(27届已发布!N4:N84,"★★★") -> 17
A18: 待发布/往年参考单位数 | B18: =COUNTA('待发布-往年参考'!D4:D138) -> 135 | D18: “待发布-往年参考”工作表
A19: 全部单位合计 | B19: =B11+B18 -> 216
A21: 省份 | B21: 已发布（家） | C21: 待发布/参考（家） | D21: 备注
A22: 福建 | B22: =COUNTIF(27届已发布!B4:B84,A22) -> 10 | C22: =COUNTIF('待发布-往年参考'!B4:B138,A22) -> 27 | D22: 学校所在地，本地单位有地缘优势
A23: 广东 | B23: =COUNTIF(27届已发布!B4:B84,A23) -> 21 | C23: =COUNTIF('待发布-往年参考'!B4:B138,A23) -> 26
A24: 上海 | B24: =COUNTIF(27届已发布!B4:B84,A24) -> 15 | C24: =COUNTIF('待发布-往年参考'!B4:B138,A24) -> 15
A25: 浙江 | B25: =COUNTIF(27届已发布!B4:B84,A25) -> 5 | C25: =COUNTIF('待发布-往年参考'!B4:B138,A25) -> 15
A26: 江苏 | B26: =COUNTIF(27届已发布!B4:B84,A26) -> 6 | C26: =COUNTIF('待发布-往年参考'!B4:B138,A26) -> 15
A27: 山东 | B27: =COUNTIF(27届已发布!B4:B84,A27) -> 4 | C27: =COUNTIF('待发布-往年参考'!B4:B138,A27) -> 10
A28: 天津 | B28: =COUNTIF(27届已发布!B4:B84,A28) -> 5 | C28: =COUNTIF('待发布-往年参考'!B4:B138,A28) -> 9
A29: 河北 | B29: =COUNTIF(27届已发布!B4:B84,A29) -> 1 | C29: =COUNTIF('待发布-往年参考'!B4:B138,A29) -> 3
A30: 辽宁 | B30: =COUNTIF(27届已发布!B4:B84,A30) -> 3 | C30: =COUNTIF('待发布-往年参考'!B4:B138,A30) -> 4
A31: 广西 | B31: =COUNTIF(27届已发布!B4:B84,A31) -> 0 | C31: =COUNTIF('待发布-往年参考'!B4:B138,A31) -> 7
A32: 海南 | B32: =COUNTIF(27届已发布!B4:B84,A32) -> 0 | C32: =COUNTIF('待发布-往年参考'!B4:B138,A32) -> 3
A33: 多地 | B33: =COUNTIF(27届已发布!B4:B84,A33) -> 11 | C33: =COUNTIF('待发布-往年参考'!B4:B138,A33) -> 1 | D33: 全国性集团/总部在内陆但在沿海有岗位
A35: 匹配度说明
A36: ★★★ 高度对口 | B36: 钢结构企业、桥梁设计/施工/检测、结构设计院、检测鉴定与腐蚀防护科研院所
A37: ★★ 较对口 | B37: 路桥港航施工技术岗、基础设施、地铁土建、设计院非结构岗、地产甲方土建工程岗
A38: ★ 一般 | B38: 房建施工管理、综合类/非土木主业企业，可作保底
A40: 投递建议
A41: 1. 先处理快截止的：北京市政总院 10-23、中冶建研院和中冶北方 10-21（需核实）、中铁广州局市政环保 10-24、中交三航局厦门批次 10-26；中交一航局、中建八局东北公司、中国能建 10-30。
A42: 2. 中建系（中建科工、中建三局、中建交通、中建一局等）大多要求先参加“中国建筑校园招聘统一考试”，先报名考试再选岗。
A43: 3. 方向最对口的：中建科工（钢结构）、中铁宝桥、中交三航南通海洋（钢结构制造）、江苏交控（硕士桥梁岗）、上海建科“建科栋梁计划”和中冶建研院（检测鉴定）、中国铁建大桥局（桥梁）。
A44: 4. 腐蚀/耐久性方向的单位岗位少但很对口：中交四航工程研究院、725所/双瑞、天科院、青岛海洋腐蚀研究所。建议在简历突出 1440h 盐雾试验和 CT、红外检测经历，直接发邮件给 HR，或请导师推荐。
A45: 5. 福建本地：厦门路桥、建发合诚、福建省建科院、厦门市建科院、中建海峡、福建建工等暂未见公告，请盯华侨大学就业网和土木学院的土建专场、双选会。
...

Sheet 重点推荐
A1: 重点推荐：与简历高度匹配（★★★）的单位
A2: A＝仍可投递，按截止日期排序；B＝已截止，建议联系HR问补录或等春招；C＝2027届公告未发布，建议主动投递简历或盯紧官方渠道。
A3: 优先级 | B3: 单位名称 | C3: 地点 | D3: 推荐方向 | E3: 截止日期 | F3: 状态 | G3: 距截止 | H3: 投递入口 | I3: 推荐理由
A4: A 立即投递 | B4: 中冶建筑研究总院有限公司（中冶建研院） | C4: 北京/天津/上海/深圳等（另有海南、湛江分支） | D4: 检测工程师、检测辅助岗、技术咨询工程师、结构工程师、节能/环保工程师、科研管理岗、博士岗 | E4: 46316 | F4: =IF(E4<TODAY(),"已截止",IF(E4=TODAY(),"今日截止",IF(E4-TODAY()<=7,"7天内截止","进行中"))) -> 7天内截止 | G4: =IF(ISNUMBER(E4),E4-TODAY(),"") -> 1 | H4: 官方招聘渠道 / 公众号 | I4: 国内检测鉴定加固龙头，钢结构检测、腐蚀评估对口；即将截止
A5: A 立即投递 | B5: 北京市市政工程设计研究总院有限公司（区域分院） | C5: 深圳/广州/东莞；东部区域含厦门 | D5: 土木工程类（市政/桥梁/道路设计） | E5: 46318 | F5: =IF(E5<TODAY(),"已截止",IF(E5=TODAY(),"今日截止",IF(E5-TODAY()<=7,"7天内截止","进行中"))) -> 7天内截止 | G5: =IF(ISNUMBER(E5),E5-TODAY(),"") -> 3 | H5: 邮箱投递（简历命名：姓名+院校+专业+意向工作地点）；官网 www.bmedi.cn | I5: 市政桥梁设计院，区域分院含厦门/深圳；结构硕士对口，即将截止
A6: A 立即投递 | B6: 中建科工集团有限公司（原中建钢构） | C6: 深圳（全国：含福建/广东/浙江/江苏/上海/山东/天津/河北/海南/广西） | D6: 建筑工程类（土木工程、智能建造、工程造价、工程管理、安全工程等）、创新业务类、职能管理类 | F6: 已启动·截止待核 | H6: PC端 ssr.cscec.com；移动端扫码；官网“人力资源→招聘信息” | I6: 国内最大钢结构集团，与钢结构工程师意向、桥梁钢结构腐蚀课题高度契合；首选，尽快投递
A7: A 立即投递 | B7: 广东省建筑设计研究院集团股份有限公司 | C7: 广州 | D7: 建筑结构设计等设计岗 | F7: 已启动·截止待核 | H7: 网申（往届入口 gdadri.zhiye.com） | I7: 省级大院，结构设计岗对口；宣传“保底年薪最高35万”（以公告为准）
A8: A 立即投递 | B8: 上海建科咨询集团“建科栋梁计划”（含上海市建筑科学研究院等9家单位） | C8: 上海（另有天津、南京、武汉宣讲） | D8: 检测工程师、结构鉴定工程师、工程咨询等 | F8: 已启动·截止待核 | H8: 建科集团官网 / 公众号；宣讲：10-17 上海总部体验日、10-23 天津、10-30 东南大学、11-06 武汉大学 | I8: 检测鉴定岗与你的CT/红外热成像/三维扫描/SEM等检测经验高度匹配；强烈推荐
A9: A 立即投递 | B9: 中交上海港湾工程设计研究院 | C9: 上海 | D9: 港工结构设计等（以公告为准） | F9: 已启动·截止待核 | H9: 中国交建人才招聘平台 | I9: 港工结构设计/检测，海洋环境耐久性与你的腐蚀课题相关
A10: A 立即投递 | B10: 江苏交通控股有限公司（2027年人才招聘第一批次） | C10: 南京 | D10: 道路工程、桥梁工程、计算机软件、人工智能、电气工程等 | F10: 已启动·截止待核 | H10: 江苏交控官网 jchc.cn“人才中心”；咨询 025-52863660 | I10: 硕士专场、含桥梁工程岗，路桥管养/检测平台大；强烈推荐
A11: A 立即投递 | B11: 中交三航（南通）海洋工程有限公司 | C11: 南通 | D11: 钢结构、预制构件制造及技术岗；本科前两年约10-18万/年 | F11: 已启动·截止待核 | H11: 中国交建人才招聘平台 | I11: 钢结构制造企业，海洋环境钢结构防腐与你课题直接相关
A12: A 立即投递 | B12: 中铁宝桥集团（含中铁宝桥（扬州）有限公司、舟山公司） | C12: 扬州（总部陕西宝鸡；另有浙江舟山） | D12: 钢桥梁制造、焊接工艺、技术质量等 | F12: 已启动·截止待核 | H12: 官网 www.crbbg.com；公告附扬州、舟山公司联系人与邮箱 | I12: 钢桥制造龙头，钢桥涂装防腐与课题直接相关
A13: A 立即投递 | B13: 中国铁建大桥工程局集团 | C13: 天津（全国） | D13: 桥梁施工技术等 | F13: 已启动·截止待核 | H13: 扫码网申；公众号“人才招聘—校园招聘”；PC端 | I13: 桥梁施工专业局，对口桥梁方向
A14: B 已截止·争取补录 | B14: 中铁二院工程集团 | C14: 杭州/济南/南宁等 | D14: 土建类（路基、桥梁、水文、港口航道与海岸工程） | E14: 46212 | F14: =IF(E14<TODAY(),"已截止",IF(E14=TODAY(),"今日截止",IF(E14-TODAY()<=7,"7天内截止","进行中"))) -> 已截止 | G14: =IF(ISNUMBER(E14),E14-TODAY(),"") -> -103 | H14: 官方招聘渠道 | I14: 已截止
A15: B 已截止·争取补录 | B15: 中铁第四勘察设计院集团（铁四院） | C15: 杭州/宁波/南京/上海等 | D15: 桥梁/结构/线路设计等 | E15: 46213 | F15: =IF(E15<TODAY(),"已截止",IF(E15=TODAY(),"今日截止",IF(E15-TODAY()<=7,"7天内截止","进行中"))) -> 已截止 | G15: =IF(ISNUMBER(E15),E15-TODAY(),"") -> -102 | H15: 官方招聘渠道 | I15: 提前批已截止，关注补录
A16: B 已截止·争取补录 | B16: 中铁上海设计院集团 | C16: 上海 | D16: 铁路/桥梁设计 | E16: 46236 | F16: =IF(E16<TODAY(),"已截止",IF(E16=TODAY(),"今日截止",IF(E16-TODAY()<=7,"7天内截止","进行中"))) -> 已截止 | G16: =IF(ISNUMBER(E16),E16-TODAY(),"") -> -79 | H16: 官方招聘渠道 | I16: 提前批已截止，关注春招补录
A17: B 已截止·争取补录 | B17: 中铁工程设计咨询集团（中铁设计） | C17: 济南 | D17: 土木建筑类设计（含桥梁院） | E17: 46249 | F17: =IF(E17<TODAY(),"已截止",IF(E17=TODAY(),"今日截止",IF(E17-TODAY()<=7,"7天内截止","进行中"))) -> 已截止 | G17: =IF(ISNUMBER(E17),E17-TODAY(),"") -> -66 | H17: 官方招聘渠道 | I17: 提前批已截止，关注补录
A18: B 已截止·争取补录 | B18: 中铁大桥勘测设计院集团（中铁大桥院） | C18: 武汉/南京/广州/芜湖 | D18: 桥梁设计、桥梁智能设计研发、桥梁科研、试验检测、施工监控、桥梁监测、桥梁养护 | E18: 46274 | F18: =IF(E18<TODAY(),"已截止",IF(E18=TODAY(),"今日截止",IF(E18-TODAY()<=7,"7天内截止","进行中"))) -> 已截止 | G18: =IF(ISNUMBER(E18),E18-TODAY(),"") -> -41 | H18: brdi.zhiye.com（PC端选择职位投递） | I18: 桥梁设计/检测/养护岗与你方向最契合；已截止，务必关注补录与春招
A19: B 已截止·争取补录 | B19: 同济设计集团（TJAD） | C19: 上海 | D19: 结构设计等设计岗 | E19: 46293 | F19: =IF(E19<TODAY(),"已截止",IF(E19=TODAY(),"今日截止",IF(E19-TODAY()<=7,"7天内截止","进行中"))) -> 已截止 | G19: =IF(ISNUMBER(E19),E19-TODAY(),"") -> -22 | H19: TJAD人才门户 careers.tjad.cn；电话 021-35377318 / 021-35377680 | I19: 顶级设计院结构岗；已截止，关注补录/春招
A20: B 已截止·争取补录 | B20: 广东精工钢结构有限公司（精工钢构集团） | C20: 广东及海外 | D20: 钢结构工程师、结构工程师、建筑工程师 | E20: 46302 | F20: =IF(E20<TODAY(),"已截止",IF(E20=TODAY(),"今日截止",IF(E20-TODAY()<=7,"7天内截止","进行中"))) -> 已截止 | G20: =IF(ISNUMBER(E20),E20-TODAY(),"") -> -13 | H20: 精工官方招聘渠道 / 公众号 | I20: 钢结构龙头民企，岗位与求职意向完全一致；已截止，建议直接联系HR问补录
A21: C 未发布·重点关注 | B21: 厦门路桥建设集团 | C21: 厦门 | D21: 桥梁隧道建设、管养 | F21: 未发布·关注官方渠道 | H21: 官网 | I21: 厦门桥梁建设管养主体，与桥梁钢结构检测高度相关，可主动投递
A22: C 未发布·重点关注 | B22: 建发合诚工程咨询股份有限公司 | C22: 厦门 | D22: 交通设计、检测、监理 | F22: 未发布·关注官方渠道 | H22: 官网 | I22: 厦门本地桥梁检测/设计上市公司，可主动投递
A23: C 未发布·重点关注 | B23: 福建省建筑科学研究院 | C23: 福州 | D23: 建筑检测鉴定、科研 | F23: 未发布·关注官方渠道 | H23: 官网 www.fjjky.com | I23: 检测鉴定对口
A24: C 未发布·重点关注 | B24: 厦门市建筑科学研究院集团 | C24: 厦门 | D24: 检测鉴定、科研 | F24: 未发布·关注官方渠道 | H24: 官网 | I24: 检测鉴定对口，厦门本地
A25: C 未发布·重点关注 | B25: 福建省交通规划设计院 | C25: 福州 | D25: 桥梁/道路设计 | F25: 未发布·关注官方渠道 | H25: 官网 | I25: 桥梁设计对口
A26: C 未发布·重点关注 | B26: 福建省建筑设计研究院 | C26: 福州 | D26: 结构设计 | F26: 未发布·关注官方渠道 | H26: 官网 | I26: 结构设计对口
A27: C 未发布·重点关注 | B27: 厦门双瑞船舶涂料有限公司（中国船舶725所） | C27: 厦门 | D27: 船舶/重防腐涂料研发、技术服务 | F27: 未发布·关注官方渠道 | H27: 官网 | I27: 重防腐涂料，与涂层腐蚀课题直接相关
A28: C 未发布·重点关注 | B28: 厦门新长诚钢构工程有限公司 | C28: 厦门 | D28: 钢结构设计、施工 | F28: 未发布·关注官方渠道 | H28: 华侨大学土木学院招聘信息栏 | I28: 本地钢结构民企，可直接联系
A29: C 未发布·重点关注 | B29: 中交第四航务工程勘察设计院（四航院） | C29: 广州 | D29: 港航水利、土木、市政、地质勘察、经管 | F29: 未发布·关注官方渠道 | H29: 中国交建人才招聘平台 / 公众号 | I29: 港工结构设计，海洋环境耐久性相关
A30: C 未发布·重点关注 | B30: 中交四航工程研究院 | C30: 广州 | D30: 科研与技术服务岗（耐久性、腐蚀防护、结构检测、数值仿真）；硕士首年15-20万 | F30: 未发布·关注官方渠道 | H30: 官网 etr.cccc4.com；中国交建人才招聘平台 | I30: 设有港珠澳大桥材料腐蚀与工程安全国家野外观测站、水工构造物耐久性重点实验室，与你课题最契合；强烈建议主动邮件投递
A31: C 未发布·重点关注 | B31: 广东华路交通科技有限公司 | C31: 广州 | D31: 路桥、隧道、岩土检测；硕士年薪约16万起 | F31: 未发布·关注官方渠道 | H31: 官网 | I31: 桥梁检测对口
A32: C 未发布·重点关注 | B32: 广东省建筑科学研究院集团 | C32: 广州 | D32: 检测鉴定、科研 | F32: 未发布·关注官方渠道 | H32: 官网 | I32: 检测鉴定对口
... A68: C 未发布·重点关注 | B68: 中国建筑科学研究院（含建研院检测中心） | C68: 北京（上海等地有分支） | D68: 检测工程师、结构、科研 | F68: 未发布·关注官方渠道 | H68: hr.cabr.com.cn | I68: 检测/结构科研对口

Sheet 27届已发布
A1: 沿海地区土木类 2027届秋招岗位汇总（已发布公告）
A2: 检索截至 2026-10-20。状态与“距截止”列按打开当天日期自动计算；“已启动·截止待核”表示已见公告但未检索到截止日。信息多为第三方转载，投递前请到官网/公众号核对。匹配度依据：结构工程学硕、桥梁钢结构腐蚀与损伤检测、钢结构/结构设计/桥梁求职意向。
A3: 序号 | B3: 省份 | C3: 城市/工作地 | D3: 单位名称 | E3: 所属集团 | F3: 企业性质 | G3: 招聘方向/岗位 | H3: 学历/专业要求 | I3: 网申入口/投递方式 | J3: 网申时间（原文） | K3: 截止日期 | L3: 状态（随当天日期自动更新） | M3: 距截止 | N3: 与简历匹配度 | O3: 匹配理由/投递建议 | P3: 信息来源
A4: 1 | B4: 福建 | C4: 厦门 | D4: 中交三航局第六工程（厦门）有限公司 | E4: 中国交建·三航局 | F4: 央企 | G4: 工程技术（港航/市政/道桥）等 | H4: 全日制本科及以上；党员、学生干部、双一流优先 | I4: 中国交建人才招聘平台网申；或简历+成绩单+证书扫描件发招聘邮箱（主题：2027届应届生+学校+专业+姓名） | J4: 2026-09-06 ~ 2026-10-04 | K4: 46299 | L4: =IF(K4<TODAY(),"已截止",IF(K4=TODAY(),"今日截止",IF(K4-TODAY()<=7,"7天内截止","进行中"))) -> 已截止 | M4: =IF(ISNUMBER(K4),K4-TODAY(),"") -> -16 | N4: ★★ | O4: 厦门本地港航央企，离学校近；网申已截止，可按公告邮箱补投并关注补录 | P4: 牛企直聘校招 campus.niuqizp.com（转载）
A5: 2 | B5: 福建 | C5: 厦门/重庆/天津 | D5: 中交三航局（厦门等地 27届秋招批次） | E5: 中国交建·三航局 | F5: 央企 | G5: 市政建设、设计装修等 | H5: 本科及以上 | I5: 中国交建人才招聘平台 | J5: 2026-08-26 ~ 2026-10-26 | K5: 46321 | L5: =IF(K5<TODAY(),"已截止",IF(K5=TODAY(),"今日截止",IF(K5-TODAY()<=7,"7天内截止","进行中"))) -> 7天内截止 | M5: =IF(ISNUMBER(K5),K5-TODAY(),"") -> 6 | N5: ★★ | O5: 聚合站标题为“中交三航局厦门”，具体用人单位以公告为准；仍在网申期 | P5: 牛企直聘校招 campus.niuqizp.com（转载）
A6: 3 | B6: 福建 | C6: 厦门 | D6: 中交上航（福建）交通建设工程有限公司 | E6: 中国交建·上海航道局 | F6: 央企 | G6: 围海造地、航道疏浚、水利、市政施工等 | H6: 本科及以上；党员优先 | I6: 扫描公告二维码网申 | J6: 2026-09-16 发布，截止待核 | L6: 已启动·截止待核 | N6: ★★ | O6: 总部在厦门；市政一级、港航二级资质 | P6: 国企招聘网 m.gwy.com/gqzp/413156.html
A7: 4 | B7: 福建 | C7: 厦门（全国） | D7: 厦门建发集团（含建发房产、联发集团、建发股份等） | E7: 厦门市国资委 | F7: 地方国企 | G7: 集团计划招600人；建发房产设土建工程、建筑/规划设计等岗 | H7: 本科及以上 | I7: 建发招聘官网（往届入口 chinacdc.zhiye.com/campus）；公众号“建发房产招聘” | J7: 2026-09-14 发布，截止待核 | L7: 已启动·截止待核 | N7: ★★ | O7: 厦门龙头国企，土建工程岗适合；广联达算量技能可加分 | P7: 牛企直聘校招 campus.niuqizp.com（转载）
A8: 5 | B8: 福建 | C8: 福州/厦门等 | D8: 福建省港口集团 | E8: 福建省国资委 | F8: 地方国企 | G8: 2027届秋季校招（岗位明细见公告） | H8: 本科及以上 | I8: 官网公告；流程：投递简历→筛选→笔面试→签约 | J8: 2026-10-14 发布，截止待核 | L8: 已启动·截止待核 | N8: ★★ | O8: 省属港口集团，可能有港口工程/基建岗 | P8: 国企招聘网 m.gwy.com（转载）
A9: 6 | B9: 福建 | C9: 莆田（全国） | D9: 三棵树涂料股份有限公司（“森计划”） | E9: 民营上市 | F9: 民企 | G9: 研发、工程技术服务、销售等 | H9: 本科及以上（国内毕业 2027.01-07） | I9: 3treesgroup.zhaopin.com →“应届生招聘-森计划”；公众号“三棵树招聘” | J9: 2026-09 起宣讲中，截止待核 | L9: 已启动·截止待核 | N9: ★★ | O9: 涂料企业，与你的涂层腐蚀课题相关（涂层性能评价、防腐工程技术服务） | P9: 牛企直聘校招 campus.niuqizp.com（转载）
A10: 7 | B10: 福建 | C10: 厦门等 | D10: 厦门象屿集团 | E10: 厦门市国资委 | F10: 地方国企 | G10: 文理工科均可；含矿山评估工程师等工程类岗 | H10: 本科及以上（毕业 2026.09-2027.08） | I10: 象屿官方招聘渠道 | J10: 2026-09 宣讲中，截止待核 | L10: 已启动·截止待核 | N10: ★ | O10: 以供应链为主，土木对口岗位少，可作保底 | P10: 牛企直聘校招 campus.niuqizp.com（转载）
A11: 8 | B11: 福建 | C11: 厦门 | D11: 厦门国贸集团股份有限公司 | E11: 厦门国贸控股 | F11: 地方国企 | G11: 2027届秋季全球校招 | H11: 本科及以上 | I11: 国贸官方招聘渠道 | J11: 2026-09-07 ~ 2026-10-05 | K11: 46300 | L11: =IF(K11<TODAY(),"已截止",IF(K11=TODAY(),"今日截止",IF(K11-TODAY()<=7,"7天内截止","进行中"))) -> 已截止 | M11: =IF(ISNUMBER(K11),K11-TODAY(),"") -> -15 | N11: ★ | O11: 以贸易为主，土木对口岗位少 | P11: 牛企直聘校招 campus.niuqizp.com（转载）
A12: 9 | B12: 福建 | C12: 泉州 | D12: 中化泉州石化有限公司 | E12: 中国中化 | F12: 央企 | G12: 2027年校园招聘（土建/设备岗以公告为准） | H12: 本科及以上 | I12: 官方招聘渠道 | J12: 2026-09-17 ~ 2026-11-15 | K12: 46341 | L12: =IF(K12<TODAY(),"已截止",IF(K12=TODAY(),"今日截止",IF(K12-TODAY()<=7,"7天内截止","进行中"))) -> 进行中 | M12: =IF(ISNUMBER(K12),K12-TODAY(),"") -> 26 | N12: ★ | O12: 石化企业，土建维护类岗位较少，备选 | P12: 牛企直聘校招 campus.niuqizp.com（转载）
A13: 10 | B13: 福建 | C13: 福州 | D13: 福建省华荣建设集团有限公司 | E13: 民营 | F13: 民企 | G13: 安全员（建筑类/土木类专业） | H13: 大专/本科 | I13: 福建人才联合网（福州大学）在线投递 | J13: 岗位截止 2027-04-30 | K13: 46507 | L13: =IF(K13<TODAY(),"已截止",IF(K13=TODAY(),"今日截止",IF(K13-TODAY()<=7,"7天内截止","进行中"))) -> 进行中 | M13: =IF(ISNUMBER(K13),K13-TODAY(),"") -> 192 | N13: ★ | O13: 福建本地施工企业，有钢结构等专业资质；岗位层级较基础，作保底 | P13: 福建人才联合网 fjrclh.fzu.edu.cn/cms/jobDetails.html?jobId=54705
A14: 11 | B14: 广东 | C14: 深圳（全国：含福建/广东/浙江/江苏/上海/山东/天津/河北/海南/广西） | D14: 中建科工集团有限公司（原中建钢构） | E14: 中国建筑 | F14: 央企 | G14: 建筑工程类（土木工程、智能建造、工程造价、工程管理、安全工程等）、创新业务类、职能管理类 | H14: 本科及以上；内地 2027.01-07 毕业；需参加中国建筑校园招聘统一考试 | I14: PC端 ssr.cscec.com；移动端扫码；官网“人力资源→招聘信息” | J14: 2026-08-28 启动；往届为 09-04 ~ 11-03 | L14: 已启动·截止待核 | N14: ★★★ | O14: 国内最大钢结构集团，与钢结构工程师意向、桥梁钢结构腐蚀课题高度契合；首选，尽快投递 | P14: 牛企直聘 campus.niuqizp.com/job-vUm5aNZtZ.html
A15: 12 | B15: 广东 | C15: 深圳/广州/东莞；东部区域含厦门 | D15: 北京市市政工程设计研究总院有限公司（区域分院） | E15: 北京市国资委 | F15: 地方国企 | G15: 土木工程类（市政/桥梁/道路设计） | H15: 北京总部：硕博；区域分支：本硕 | I15: 邮箱投递（简历命名：姓名+院校+专业+意向工作地点）；官网 www.bmedi.cn | J15: 2026-09-25 ~ 2026-10-23 | K15: 46318 | L15: =IF(K15<TODAY(),"已截止",IF(K15=TODAY(),"今日截止",IF(K15-TODAY()<=7,"7天内截止","进行中"))) -> 7天内截止 | M15: =IF(ISNUMBER(K15),K15-TODAY(),"") -> 3 | N15: ★★★ | O15: 市政桥梁设计院，区域分院含厦门/深圳；结构硕士对口，即将截止 | P15: 牛企直聘 campus.niuqizp.com/job-vsY5MaC5Z.html
A16: 13 | B16: 广东 | C16: 广州 | D16: 广东省建筑设计研究院集团股份有限公司 | E16: 广东省国资委 | F16: 地方国企（上市） | G16: 建筑结构设计等设计岗 | H16: 本科及以上；国内毕业 2027.01.01-2027.08.31 | I16: 网申（往届入口 gdadri.zhiye.com） | J16: 2026-09-02 启动，截止待核 | L16: 已启动·截止待核 | N16: ★★★ | O16: 省级大院，结构设计岗对口；宣传“保底年薪最高35万”（以公告为准） | P16: 牛企直聘校招 campus.niuqizp.com（转载）
A17: 14 | B17: 广东 | C17: 广东及海外 | D17: 广东精工钢结构有限公司（精工钢构集团） | E17: 精工控股（民营上市） | F17: 民企 | G17: 钢结构工程师、结构工程师、建筑工程师 | H17: 本科及以上 | I17: 精工官方招聘渠道 / 公众号 | J17: 2026-09-09 ~ 2026-10-07 | K17: 46302 | L17: =IF(K17<TODAY(),"已截止",IF(K17=TODAY(),"今日截止",IF(K17-TODAY()<=7,"7天内截止","进行中"))) -> 已截止 | M17: =IF(ISNUMBER(K17),K17-TODAY(),"") -> -13 | N17: ★★★ | O17: 钢结构龙头民企，岗位与求职意向完全一致；已截止，建议直接联系HR问补录 | P17: 牛企直聘校招 campus.niuqizp.com（转载）
A18: 15 | B18: 广东 | C18: 深圳（华南公司，辖广东、海南） | D18: 中建交通建设集团有限公司 | E18: 中国建筑 | F18: 央企 | G18: 基础设施（路桥/轨交/市政）工程技术等 | H18: 本科及以上；需中建统一考试 | I18: 中建交通招聘平台 / 中国建筑网申门户 | J18: 2026-09-10 ~ 2026-11-10 | K18: 46336 | L18: =IF(K18<TODAY(),"已截止",IF(K18=TODAY(),"今日截止",IF(K18-TODAY()<=7,"7天内截止","进行中"))) -> 进行中 | M18: =IF(ISNUMBER(K18),K18-TODAY(),"") -> 21 | N18: ★★ | O18: 路桥施工技术岗，对口桥梁方向 | P18: 牛企直聘 campus.niuqizp.com/job-v8l5CMM5N.html
A19: 16 | B19: 广东 | C19: 广州/深圳 | D19: 中建三局华南公司 | E19: 中国建筑·中建三局 | F19: 央企 | G19: 房屋建筑、基础设施、勘察设计、金融财务、职能管理（约200人） | H19: 本科及以上；需中建统一考试 | I19: 中建三局招聘网（第三方称 cscec3b.zhiye.com，请核实） | J19: 2026-09-04 发布，截止待核 | L19: 已启动·截止待核 | N19: ★★ | O19: 超高层、钢结构施工项目多，技术岗可选 | P19: 牛企直聘校招 campus.niuqizp.com（转载）
A20: 17 | B20: 广东 | C20: 广州等 | D20: 中建四局交通投资建设有限公司 | E20: 中国建筑·中建四局 | F20: 央企 | G20: 全序列岗位（约15人）；薪资 8.5-9.5k | H20: 以公告为准 | I20: 中国建筑网申门户 | J20: 2026-09 启动，截止待核 | L20: 已启动·截止待核 | N20: ★★ | O20: 交通基础设施方向 | P20: 牛企直聘校招 campus.niuqizp.com（转载）
A21: 18 | B21: 广东 | C21: 广州 | D21: 中交第四航务工程局第二工程有限公司 | E21: 中国交建·四航局 | F21: 央企 | G21: 工程技术、船机管理、财务、综合管理等；本科年薪10-13万，研究生12-16万 | H21: 本科及以上 | I21: 邮箱/官网/二维码网申；流程：网申→测评→筛选→笔面→offer→三方 | J21: 2026-09-03 启动，截止待核 | L21: 已启动·截止待核 | N21: ★★ | O21: 华南港航施工主力 | P21: 牛企直聘校招 campus.niuqizp.com（转载）
A22: 19 | B22: 广东 | C22: 惠州 | D22: 中交第四航务工程局第八工程有限公司 | E22: 中国交建·四航局 | F22: 央企 | G22: 工程技术、质量管理、机械设备、工程造价、安全管理、财务、党建综合 | H22: 本科及以上 | I22: 中国交建人才招聘平台 | J22: 2026-08-28 发布，截止待核 | L22: 已启动·截止待核 | N22: ★★ | O22: 港航/市政施工；造价岗可用广联达技能 | P22: 牛企直聘校招 campus.niuqizp.com（转载）
A23: 20 | B23: 广东 | C23: 广州 | D23: 中铁广州工程局集团（集团校招） | E23: 中国中铁 | F23: 央企 | G23: 工程技术等 | H23: 全日制公办本科及以上；专业排名靠前、党员、学生干部优先 | I23: 中国中铁官网 www.crec.cn“人才招聘” / 官方公众号 | J23: 2026-08 底启动，截止待核 | L23: 已启动·截止待核 | N23: ★★ | O23: 桥隧施工较多；你本科专业排名第一是加分项 | P23: 牛企直聘校招 campus.niuqizp.com（转载）；国企招聘网 m.gwy.com（转载）
A24: 21 | B24: 广东 | C24: 广州 | D24: 中铁广州工程局市政环保公司 | E24: 中国中铁·中铁广州局 | F24: 央企 | G24: 市政/环保工程技术 | H24: 本科及以上 | I24: 同中铁广州局 | J24: 2026-08-24 ~ 2026-10-24 | K24: 46319 | L24: =IF(K24<TODAY(),"已截止",IF(K24=TODAY(),"今日截止",IF(K24-TODAY()<=7,"7天内截止","进行中"))) -> 7天内截止 | M24: =IF(ISNUMBER(K24),K24-TODAY(),"") -> 4 | N24: ★★ | O24: 即将截止 | P24: 牛企直聘校招 campus.niuqizp.com（转载）
A25: 22 | B25: 广东 | C25: 广州 | D25: 广州地铁集团有限公司 | E25: 广州市国资委 | F25: 地方国企 | G25: 2027届全球校招（约150人；土建类岗位以岗位表为准） | H25: 本科及以上 | I25: 广州地铁官网“人才招聘”；公众号“下一站广州地铁”；需完成在线测评 | J25: 2026-09-10 ~ 2026-11-10（转载称测评截止 10-05，需核实） | K25: 46336 | L25: =IF(K25<TODAY(),"已截止",IF(K25=TODAY(),"今日截止",IF(K25-TODAY()<=7,"7天内截止","进行中"))) -> 进行中 | M25: =IF(ISNUMBER(K25),K25-TODAY(),"") -> 21 | N25: ★★ | O25: 地铁土建/结构维护岗可关注；先确认测评是否仍开放 | P25: 牛企直聘校招 campus.niuqizp.com（转载）
A26: 23 | B26: 广东 | C26: 广州 | D26: 中国能建广东火电工程有限公司 | E26: 中国能建 | F26: 央企 | G26: 工程技术管理、项目管理、职能管理 | H26: 本科及以上 | I26: 中国能建招聘平台 ceec.iguopin.com | J26: 聚合站显示截止 2026-12-16（二次检索未能确认） | K26: 46372 | L26: =IF(K26<TODAY(),"已截止",IF(K26=TODAY(),"今日截止",IF(K26-TODAY()<=7,"7天内截止","进行中"))) -> 进行中 | M26: =IF(ISNUMBER(K26),K26-TODAY(),"") -> 57 | N26: ★★ | O26: 电力工程施工，土建技术岗可投；截止日期务必核实 | P26: 牛企直聘校招 campus.niuqizp.com（转载）
A27: 24 | B27: 广东 | C27: 深圳 | D27: 中海地产（中国海外发展） | E27: 中国建筑 | F27: 央企 | G27: “海之子”：土建工程岗、机电工程岗等 | H27: 本科及以上；毕业 2026.09-2027.12 | I27: 中海招聘官网 / 公众号 | J27: 2026-10 已启动，截止待核 | L27: 已启动·截止待核 | N27: ★★ | O27: 地产甲方土建工程岗，平台好、竞争激烈 | P27: 国企招聘网 m.gwy.com/gqzp/414596.html
A28: 25 | B28: 广东 | C28: 深圳（全国） | D28: 招商局集团（集团统一校招） | E28: 国务院国资委 | F28: 央企 | G28: 港口、交通、地产、工程等二级单位岗位 | H28: 本科及以上 | I28: 招商局集团招聘官网 | J28: 2026-09 上旬开始网申，各单位截止不同 | L28: 已启动·截止待核 | N28: ★★ | O28: 下属有港口、交通、工程咨询单位，可逐个查看 | P28: 国企招聘网 m.gwy.com（转载）
A29: 26 | B29: 广东 | C29: 广州/深圳 | D29: 中建四局建设投资有限公司 | E29: 中国建筑·中建四局 | F29: 央企 | G29: 技术管理、质量管控、资料台账管理（约5人） | H29: 本科及以上；需中国建筑高校毕业生接收考试成绩 | I29: 中国建筑网申门户 | J29: 2026-09-02 发布，截止待核 | L29: 已启动·截止待核 | N29: ★ | O29: 名额少，偏投资管理 | P29: 牛企直聘校招 campus.niuqizp.com（转载）
A30: 27 | B30: 广东 | C30: 深圳 | D30: 中铁广州工程局深圳工程有限公司（见习生） | E30: 中国中铁·中铁广州局 | F30: 央企 | G30: 2027届见习生（30人） | H30: 本科及以上 | I30: 同中铁广州局 | J30: 已发布，截止待核 | L30: 已启动·截止待核 | N30: ★ | O30: 见习性质，可作为进入通道 | P30: 牛企直聘校招 campus.niuqizp.com（转载）
A31: 28 | B31: 广东 | C31: 深圳（全国） | D31: 华润置地（“百匠新人”） | E31: 华润集团 | F31: 央企 | G31: 约300人；工程等岗；8-13k | H31: 本科及以上；毕业 2026.09.01-2027.08.31 | I31: 华润置地招聘官网 / 公众号 | J31: 2026-09 发布，截止待核 | L31: 已启动·截止待核 | N31: ★ | O31: 地产工程管理方向 | P31: 牛企直聘校招 campus.niuqizp.com（转载）
A32: 29 | B32: 广东 | C32: 深圳 | D32: 招商局蛇口工业区（招商蛇口） | E32: 招商局集团 | F32: 央企 | G32: 工程管理类等 | H32: 本科及以上 | I32: 公众号“招商蛇口招聘” / 招商蛇口招聘官网 | J32: 2026-09-06 ~ 2026-10-04 | K32: 46299 | L32: =IF(K32<TODAY(),"已截止",IF(K32=TODAY(),"今日截止",IF(K32-TODAY()<=7,"7天内截止","进行中"))) -> 已截止 | M32: =IF(ISNUMBER(K32),K32-TODAY(),"") -> -16 | N32: ★ | O32: 已截止，关注补录 | P32: 牛企直聘校招 campus.niuqizp.com（转载）
A33: 30 | B33: 广东 | C33: 广州（全国） | D33: 保利发展控股集团 | E33: 中国保利 | F33: 央企 | G33: “启航计划”管培生、营销、合伙人等（工程岗待核） | H33: 本科及以上；毕业 2026.09-2027.09 | I33: 保利官方招聘网站 | J33: 27届已启动，截止待核 | L33: 已启动·截止待核 | N33: ★ | O33: 地产，工程岗不确定 | P33: 牛企直聘校招 campus.niuqizp.com（转载）
A34: 31 | B34: 广东 | C34: 深圳/广州/珠海等 | D34: 佳兆业集团 | E34: 民营 | F34: 民企 | G34: 2027届全球校招（工程岗以公告为准） | H34: 本科及以上 | I34: 佳兆业官方招聘渠道 | J34: 2026-09-21 ~ 2026-11-21 | K34: 46347 | L34: =IF(K34<TODAY(),"已截止",IF(K34=TODAY(),"今日截止",IF(K34-TODAY()<=7,"7天内截止","进行中"))) -> 进行中 | M34: =IF(ISNUMBER(K34),K34-TODAY(),"") -> 32 | N34: ★ | O34: 民营地产，作保底 | P34: 牛企直聘校招 campus.niuqizp.com（转载）
A35: 32 | B35: 上海 | C35: 上海（另有天津、南京、武汉宣讲） | D35: 上海建科咨询集团“建科栋梁计划”（含上海市建筑科学研究院等9家单位） | E35: 上海市国资委 | F35: 地方国企 | G35: 检测工程师、结构鉴定工程师、工程咨询等 | H35: 本科/硕士 | I35: 建科集团官网 / 公众号；宣讲：10-17 上海总部体验日、10-23 天津、10-30 东南大学、11-06 武汉大学 | J35: 2026-09 发布，截止待核 | L35: 已启动·截止待核 | N35: ★★★ | O35: 检测鉴定岗与你的CT/红外热成像/三维扫描/SEM等检测经验高度匹配；强烈推荐 | P35: 牛企直聘校招 campus.niuqizp.com（转载）
A36: 33 | B36: 上海 | C36: 上海 | D36: 同济设计集团（TJAD） | E36: 同济大学 | F36: 高校企业 | G36: 结构设计等设计岗 | H36: 本科及以上（设计岗多要求硕士） | I36: TJAD人才门户 careers.tjad.cn；电话 021-35377318 / 021-35377680 | J36: 2026-09-09 启动；转载称简历投递 09-08 ~ 09-28 | K36: 46293 | L36: =IF(K36<TODAY(),"已截止",IF(K36=TODAY(),"今日截止",IF(K36-TODAY()<=7,"7天内截止","进行中"))) -> 已截止 | M36: =IF(ISNUMBER(K36),K36-TODAY(),"") -> -22 | N36: ★★★ | O36: 顶级设计院结构岗；已截止，关注补录/春招 | P36: 牛企直聘校招 campus.niuqizp.com（转载）
A37: 34 | B37: 上海 | C37: 上海 | D37: 中交上海港湾工程设计研究院 | E37: 中国交建 | F37: 央企 | G37: 港工结构设计等（以公告为准） | H37: 硕士为主 | I37: 中国交建人才招聘平台 | J37: 27届已发布，截止待核 | L37: 已启动·截止待核 | N37: ★★★ | O37: 港工结构设计/检测，海洋环境耐久性与你的腐蚀课题相关 | P37: 牛企直聘校招 campus.niuqizp.com（转载）（未见原文）
A38: 35 | B38: 上海 | C38: 上海 | D38: 中铁上海设计院集团 | E38: 中国铁建 | F38: 央企 | G38: 铁路/桥梁设计 | H38: 硕士及以上 | I38: 官方招聘渠道 | J38: 2026-07-05 ~ 2026-08-02 | K38: 46236 | L38: =IF(K38<TODAY(),"已截止",IF(K38=TODAY(),"今日截止",IF(K38-TODAY()<=7,"7天内截止","进行中"))) -> 已截止 | M38: =IF(ISNUMBER(K38),K38-TODAY(),"") -> -79 | N38: ★★★ | O38: 提前批已截止，关注春招补录 | P38: 牛企直聘校招 campus.niuqizp.com（转载）
A39: 36 | B39: 上海 | C39: 上海 | D39: 上海建科工程咨询有限公司 | E39: 上海建科集团 | F39: 地方国企 | G39: 工程咨询/监理 | H39: 本科及以上 | I39: 官方招聘渠道 | J39: 2026-09-21 ~ 2026-10-19 | K39: 46314 | L39: =IF(K39<TODAY(),"已截止",IF(K39=TODAY(),"今日截止",IF(K39-TODAY()<=7,"7天内截止","进行中"))) -> 已截止 | M39: =IF(ISNUMBER(K39),K39-TODAY(),"") -> -1 | N39: ★★ | O39: 刚截止，可改投建科栋梁计划其他单位 | P39: 牛企直聘 campus.niuqizp.com/schedule-7y8UNznZt.html
A40: 37 | B40: 上海 | C40: 上海 | D40: 上海建工集团（一建~七建、机施、基础、市政等） | E40: 上海市国资委 | F40: 地方国企 | G40: 工程技术、施工管理等 | H40: 本科及以上 | I40: 上海建工官网 / 公众号“上海建工” | J40: 2026-09-16 公告已发，截止待核 | L40: 已启动·截止待核 | N40: ★★ | O40: 上海本地施工龙头，钢结构/大跨结构项目多 | P40: 牛企直聘校招 campus.niuqizp.com（转载）
...

Sheet 待发布-往年参考
A1: 重点关注名单：2027届公告暂未检索到（或仅有往年/实习信息）
A2: 这些单位每年都招土木类毕业生，但截至 2026-10-20 未在可检索渠道看到 2027届秋招公告。请关注其官网、公众号及学校双选会；往年时间仅供参考，不代表今年安排。
A3: 序号 | B3: 省份 | C3: 城市 | D3: 单位名称 | E3: 所属集团 | F3: 企业性质 | G3: 主要招聘方向 | H3: 官方渠道 | I3: 往年/最近一次招聘时间（参考） | J3: 与简历匹配度 | K3: 建议
A4: 1 | B4: 福建 | C4: 厦门 | D4: 厦门路桥建设集团 | E4: 厦门市国资委 | F4: 地方国企 | G4: 桥梁隧道建设、管养 | H4: 官网 | I4: 未检索到 | J4: ★★★ | K4: 厦门桥梁建设管养主体，与桥梁钢结构检测高度相关，可主动投递
A5: 2 | B5: 福建 | C5: 厦门 | D5: 建发合诚工程咨询股份有限公司 | E5: 建发集团（上市） | F5: 国企控股 | G5: 交通设计、检测、监理 | H5: 官网 | I5: 未检索到 | J5: ★★★ | K5: 厦门本地桥梁检测/设计上市公司，可主动投递
A6: 3 | B6: 福建 | C6: 福州 | D6: 福建省建筑科学研究院 | E6: 福建建工 | F6: 地方国企 | G6: 建筑检测鉴定、科研 | H6: 官网 www.fjjky.com | I6: 未检索到 | J6: ★★★ | K6: 检测鉴定对口
A7: 4 | B7: 福建 | C7: 厦门 | D7: 厦门市建筑科学研究院集团 | E7: 厦门市国资委 | F7: 地方国企 | G7: 检测鉴定、科研 | H7: 官网 | I7: 未检索到 | J7: ★★★ | K7: 检测鉴定对口，厦门本地
A8: 5 | B8: 福建 | C8: 福州 | D8: 福建省交通规划设计院 | E8: 福建省交通系统 | F8: 地方国企 | G8: 桥梁/道路设计 | H8: 官网 | I8: 未检索到 | J8: ★★★ | K8: 桥梁设计对口
A9: 6 | B9: 福建 | C9: 福州 | D9: 福建省建筑设计研究院 | E9: 福建建工 | F9: 地方国企 | G9: 结构设计 | H9: 官网 | I9: 未检索到 | J9: ★★★ | K9: 结构设计对口
A10: 7 | B10: 福建 | C10: 厦门 | D10: 厦门双瑞船舶涂料有限公司（中国船舶725所） | E10: 中国船舶 | F10: 央企 | G10: 船舶/重防腐涂料研发、技术服务 | H10: 官网 | I10: 未检索到 | J10: ★★★ | K10: 重防腐涂料，与涂层腐蚀课题直接相关
A11: 8 | B11: 福建 | C11: 厦门 | D11: 厦门新长诚钢构工程有限公司 | E11: 民营 | F11: 民企 | G11: 钢结构设计、施工 | H11: 华侨大学土木学院招聘信息栏 | I11: 往年曾参加华侨大学土建网络专场 | J11: ★★★ | K11: 本地钢结构民企，可直接联系
A12: 9 | B12: 福建 | C12: 福州 | D12: 中建海峡建设发展有限公司 | E12: 中国建筑 | F12: 央企 | G12: 工程技术、商务预算、安全机械、建筑设计、基础设施 | H12: 中国建筑网申门户 + 统一考试 | I12: 26届：2025-09-17 ~ 11-16 | J12: ★★ | K12: 福建本地中建主力，重点盯官方公众号
A13: 10 | B13: 福建 | C13: 福州/厦门 | D13: 中建七局（福建区域） | E13: 中国建筑 | F13: 央企 | G13: 工程技术等 | H13: 中国建筑统一门户 + 统一考试 | I13: 26届：2025-10-01 起长期招聘 | J13: ★★ | K13: 福州、厦门有岗位
A14: 11 | B14: 福建 | C14: 福州 | D14: 福建建工集团（含福建一建、二建、五建等） | E14: 福建省国资委 | F14: 地方国企 | G14: 施工技术；旗下有福建省建筑设计研究院 | H14: 官网 / 高校双选会 | I14: 未检索到 | J14: ★★ | K14: 曾参加华侨大学双选会，留意学校招聘会
A15: 12 | B15: 福建 | C15: 福州 | D15: 福建省交通运输集团（含福建路桥建设） | E15: 福建省国资委 | F15: 地方国企 | G15: 路桥施工 | H15: 官网 | I15: 未检索到 | J15: ★★ | K15: 福建桥梁施工主力
... A17: 14 | B17: 福建 | C17: 厦门 | D17: 厦门轨道建设发展集团（厦门地铁） | E17: 厦门市国资委 | F17: 地方国企 | G17: 地铁建设/运营 | H17: 官网 / 公众号 | I17: 26届春招截止 2026-03-15 | J17: ★★ | K17: 多在春季招聘
A18: 15 | B18: 福建 | C18: 厦门 | D18: 厦门港务控股集团 | E18: 厦门市国资委 | F18: 地方国企 | G18: 港口工程等 | H18: 官网 | I18: 26届：2025-09-16 ~ 11-15 | J18: ★★
A19: 16 | B19: 福建 | C19: 厦门 | D19: 厦门市政集团 | E19: 厦门市国资委 | F19: 地方国企 | G19: 市政建设 | H19: 官网 | I19: 未检索到 | J19: ★★
A20: 17 | B20: 福建 | C20: 福州 | D20: 中国电建福建省电力勘测设计院 | E20: 中国电建 | F20: 央企 | G20: 电气/土建设计、建筑设计、造价 | H20: fedi.zhiye.com | I20: 27届暑期实习：2026-04-28 ~ 05-28（硕士+） | J20: ★★ | K20: 秋招可能随中国电建集团批次发布
A21: 18 | B21: 福建 | C21: 福州 | D21: 福州地铁集团 | E21: 福州市国资委 | F21: 地方国企 | G21: 地铁建设运营 | H21: 官网 | I21: 26届专场：2026-04-16 ~ 05-14 | J21: ★★
A22: 19 | B22: 福建 | C22: 泉州 | D22: 泉州城建集团 | E22: 泉州市国资委 | F22: 地方国企 | G22: 城市建设 | H22: 官网 | I22: 未检索到 | J22: ★★ | K22: 华侨大学泉州校区所在地，学院曾办泉州国企专场
A23: 20 | B23: 福建 | C23: 厦门/福州/广州/北京 | D23: 国机陆原工程设计研究有限公司 | E23: 中国机械工业集团 | F23: 央企 | G23: 建筑设计、结构工程等 | H23: 公众号“国机陆原” | I23: 27届实习：2026-06-18 ~ 07-18 | J23: ★★
A24: 21 | B24: 福建 | C24: 福州 | D24: 中国一冶福州分公司 | E24: 中国中冶 | F24: 央企 | G24: 施工员、技术员（含钢结构施工） | H24: 福建人才联合网（福州大学） | I24: 未标届别 | J24: ★★
A25: 22 | B25: 福建 | C25: 厦门 | D25: 厦门特房集团（特房建工） | E25: 厦门市国资委 | F25: 地方国企 | G25: 房建施工/开发 | H25: 官网 | I25: 未检索到 | J25: ★
A26: 23 | B26: 福建 | C26: 厦门 | D26: 厦门安居集团 | E26: 厦门市国资委 | F26: 地方国企 | G26: 保障房建设 | H26: 官网 | I26: 未检索到 | J26: ★
A27: 24 | B27: 福建 | C27: 福州 | D27: 福州城投集团 | E27: 福州市国资委 | F27: 地方国企 | G27: 城建投资 | H27: 官网 | I27: 26届春招补录：2026-05 | J27: ★
A28: 25 | B28: 福建 | C28: 厦门 | D28: 上海勘察设计研究院（集团）厦门分公司 | E28: 上海城投 | F28: 地方国企 | G28: 勘察、测绘、岩土 | H28: 华侨大学土木学院招聘信息栏 | I28: 往年曾在华侨大学招聘（本科） | J28: ★
A29: 26 | B29: 福建 | C29: 福建 | D29: 陕建丝路（福建）建设发展有限公司 | E29: 陕西建工 | F29: 地方国企 | G29: 施工技术 | H29: 华侨大学土木学院招聘信息栏 | I29: 往年曾在华侨大学招聘 | J29: ★
A30: 27 | B30: 福建 | C30: 福州 | D30: 福建六建集团 | E30: 民营 | F30: 民企 | G30: 施工技术、内业资料 | H30: 官网 | I30: 2020届资料 | J30: ★
A31: 28 | B31: 广东 | C31: 广州 | D31: 中交第四航务工程勘察设计院（四航院） | E31: 中国交建 | F31: 央企 | G31: 港航水利、土木、市政、地质勘察、经管 | H31: 中国交建人才招聘平台 / 公众号 | I31: 26届：2025-09-18 ~ 11-17 | J31: ★★★ | K31: 港工结构设计，海洋环境耐久性相关
A32: 29 | B32: 广东 | C32: 广州 | D32: 中交四航工程研究院 | E32: 中国交建 | F32: 央企 | G32: 科研与技术服务岗（耐久性、腐蚀防护、结构检测、数值仿真）；硕士首年15-20万 | H32: 官网 etr.cccc4.com；中国交建人才招聘平台 | I32: 26届：2025-09-06 ~ 11-05（硕士+，20人） | J32: ★★★ | K32: 设有港珠澳大桥材料腐蚀与工程安全国家野外观测站、水工构造物耐久性重点实验室，与你课题最契合；强烈建议主动邮件投递
A33: 30 | B33: 广东 | C33: 广州 | D33: 广东华路交通科技有限公司 | E33: 广东省交通集团 | F33: 地方国企 | G33: 路桥、隧道、岩土检测；硕士年薪约16万起 | H33: 官网 | I33: 26届：2025-10 发布 | J33: ★★★ | K33: 桥梁检测对口
A34: 31 | B34: 广东 | C34: 广州 | D34: 广东省建筑科学研究院集团 | E34: 广东建工 | F34: 地方国企 | G34: 检测鉴定、科研 | H34: 官网 | I34: 26届：截至 2026-07-31 | J34: ★★★ | K34: 检测鉴定对口
A35: 32 | B35: 广东 | C35: 广州 | D35: 广东省交通规划设计研究院 | E35: 广东省交通集团 | F35: 地方国企 | G35: 桥梁/道路设计 | H35: 官网 | I35: 未检索到 | J35: ★★★
A36: 33 | B36: 广东 | C36: 广州 | D36: 广州市市政工程设计研究总院 | E36: 广州市国资委 | F36: 地方国企 | G36: 市政/桥梁设计（26届16人，研究生13人） | H36: 官网 | I36: 26届：2025-12 发布 | J36: ★★★
A37: 34 | B37: 广东 | C37: 深圳 | D37: 深圳市市政设计研究院 | E37: 深圳市属 | F37: 国企 | G37: 市政/桥梁设计 | H37: 官网 | I37: 未检索到 | J37: ★★★
A38: 35 | B38: 广东 | C38: 广州 | D38: 华南理工大学建筑设计研究院 | E38: 华南理工大学 | F38: 高校企业 | G38: 结构设计 | H38: 官网 | I38: 往年曾参加华侨大学土建网络专场 | J38: ★★★
A39: 36 | B39: 广东 | C39: 广州 | D39: 中交第四航务工程局（总部） | E39: 中国交建 | F39: 央企 | G39: 港航工程技术 | H39: 中国交建人才招聘平台 | I39: 未检索到总部公告 | J39: ★★
A40: 37 | B40: 广东 | C40: 广州南沙 | D40: 中铁隧道局集团 | E40: 中国中铁 | F40: 央企 | G40: 土木、机械、电气等 | H40: 中国中铁招聘 | I40: 26届：截至 2025-11-07 | J40: ★★
A41: 38 | B41: 广东 | C41: 珠海横琴 | D41: 中国铁建港航局集团 | E41: 中国铁建 | F41: 央企 | G41: 工程技术、施工管理、港航运管 | H41: 官网 / 公众号 | I41: 26届：2025-09-14 ~ 11-13 | J41: ★★
...

Sheet 网申入口
A1: 主要官方网申入口与信息渠道
A2: 网址来自检索结果中的公告转载，个别为往届入口，打不开时请从企业官网“人才招聘”进入。
A3: 平台/集团 | B3: 网址/入口 | C3: 说明
A4: 中国建筑（中建各工程局/专业公司） | B4: 各单位网申门户，如中建一局 recruit.cscec.com、中建科工 ssr.cscec.com、中建八局 job.cscec8b.com.cn | C4: 多数单位要求先参加“中国建筑高校毕业生接收考试/校园招聘统一考试”，成绩通常各单位通用；建议先报名考试
A5: 中国交建（中交各局/院） | B5: 中国交建人才招聘平台（往届域名 ccccltd.zhiye.com）；公众号“中国交建人才招聘平台” | C5: 各子公司分别发布，截止时间差异大
A6: 中国中铁 | B6: 中国中铁官网 www.crec.cn →“人才招聘” | C6: 按单位名称检索公告
A7: 中国铁建 | B7: 中国铁建官网“人才招聘”栏目 + 各子公司公众号 | C7: 如中国铁建大桥局：公众号“人才招聘—校园招聘”
A8: 中国电建 | B8: zhaopin.powerchina.cn | C8: 集团公告 2026-09-22
A9: 中国能建 | B9: ceec.iguopin.com（另有转载称 zhaopin.ceec.net.cn） | C9: 集团网申 2026-08-31 ~ 10-30
A10: 国聘（央企/国企汇总） | B10: www.iguopin.com / 公众号“国聘” | C10: 可按地区、行业、学历筛选
A11: 国家大学生就业服务平台（24365） | B11: www.ncss.cn | C11: 教育部官方平台
A12: 交通运输部所属事业单位统一招聘 | B12: rccp.jtzyzg.org.cn | C12: 天科院等部属院所
A13: 华侨大学就业创业指导中心 | B13: bys.hqu.edu.cn；土木学院就业信息 civil.hqu.edu.cn/jyxx.htm | C13: 留意本校秋季双选会、土建专场
A14: 福建人才联合网（福州大学） | B14: fjrclh.fzu.edu.cn | C14: 福建本地企业较多
... A16: 国企招聘网（第三方） | B16: m.gwy.com | C16: 转载信息，以官方公告为准
